Workbook

Sheet Tổng quan
A1: BỘ TEST CASE – BACH MAI HOSPITAL (BMH)
A2: Kiểm thử chức năng thủ công – Vòng 1 – Phiên bản 1.0
A4: Môi trường kiểm thử | B4: Windows 11 / Microsoft Edge 155.0.4283.62 (64-bit) / Môi trường kiểm thử, phiên bản 1.0
A5: Người thực hiện | B5: Tran Liinh
A6: Thời gian thực hiện | B6: 19/10/2026 – 23/10/2026
A7: Nguồn dữ liệu | B7: Test case: atm-exporter_1.xlsx; kết quả thực thi và lỗi: atm-report.xlsx, list_bug.csv
A9: THỐNG KÊ THEO CHỨC NĂNG
A10: Chức năng | B10: Tổng TC | C10: Pass | D10: Fail | E10: Chưa thực thi | F10: Đã thực thi | G10: Tỷ lệ Pass
A11: 01 - Đăng nhập | B11: =COUNTIF('Test Case'!$C$2:$C$300,A11) -> 9 | C11: =COUNTIFS('Test Case'!$C$2:$C$300,$A11,'Test Case'!$M$2:$M$300,"Pass") -> 8 | D11: =COUNTIFS('Test Case'!$C$2:$C$300,$A11,'Test Case'!$M$2:$M$300,"Fail") -> 0 | E11: =COUNTIFS('Test Case'!$C$2:$C$300,$A11,'Test Case'!$M$2:$M$300,"Chưa thực thi") -> 1 | F11: =C11+D11 -> 8 | G11: =IF(F11=0,0,C11/F11) -> 1
A12: 02 - Quản lý bệnh nhân | B12: =COUNTIF('Test Case'!$C$2:$C$300,A12) -> 22 | C12: =COUNTIFS('Test Case'!$C$2:$C$300,$A12,'Test Case'!$M$2:$M$300,"Pass") -> 21 | D12: =COUNTIFS('Test Case'!$C$2:$C$300,$A12,'Test Case'!$M$2:$M$300,"Fail") -> 0 | E12: =COUNTIFS('Test Case'!$C$2:$C$300,$A12,'Test Case'!$M$2:$M$300,"Chưa thực thi") -> 1 | F12: =C12+D12 -> 21 | G12: =IF(F12=0,0,C12/F12) -> 1
A13: 03 - Quản lý giấy khám bệnh | B13: =COUNTIF('Test Case'!$C$2:$C$300,A13) -> 50 | C13: =COUNTIFS('Test Case'!$C$2:$C$300,$A13,'Test Case'!$M$2:$M$300,"Pass") -> 50 | D13: =COUNTIFS('Test Case'!$C$2:$C$300,$A13,'Test Case'!$M$2:$M$300,"Fail") -> 0 | E13: =COUNTIFS('Test Case'!$C$2:$C$300,$A13,'Test Case'!$M$2:$M$300,"Chưa thực thi") -> 0 | F13: =C13+D13 -> 50 | G13: =IF(F13=0,0,C13/F13) -> 1
A14: 04 - Quản lý thuốc | B14: =COUNTIF('Test Case'!$C$2:$C$300,A14) -> 65 | C14: =COUNTIFS('Test Case'!$C$2:$C$300,$A14,'Test Case'!$M$2:$M$300,"Pass") -> 65 | D14: =COUNTIFS('Test Case'!$C$2:$C$300,$A14,'Test Case'!$M$2:$M$300,"Fail") -> 0 | E14: =COUNTIFS('Test Case'!$C$2:$C$300,$A14,'Test Case'!$M$2:$M$300,"Chưa thực thi") -> 0 | F14: =C14+D14 -> 65 | G14: =IF(F14=0,0,C14/F14) -> 1
A15: 05 - Quản lý thẻ BHYT | B15: =COUNTIF('Test Case'!$C$2:$C$300,A15) -> 74 | C15: =COUNTIFS('Test Case'!$C$2:$C$300,$A15,'Test Case'!$M$2:$M$300,"Pass") -> 69 | D15: =COUNTIFS('Test Case'!$C$2:$C$300,$A15,'Test Case'!$M$2:$M$300,"Fail") -> 5 | E15: =COUNTIFS('Test Case'!$C$2:$C$300,$A15,'Test Case'!$M$2:$M$300,"Chưa thực thi") -> 0 | F15: =C15+D15 -> 74 | G15: =IF(F15=0,0,C15/F15) -> 0.93243243
A16: 06 - Lịch làm việc bác sĩ | B16: =COUNTIF('Test Case'!$C$2:$C$300,A16) -> 79 | C16: =COUNTIFS('Test Case'!$C$2:$C$300,$A16,'Test Case'!$M$2:$M$300,"Pass") -> 76 | D16: =COUNTIFS('Test Case'!$C$2:$C$300,$A16,'Test Case'!$M$2:$M$300,"Fail") -> 3 | E16: =COUNTIFS('Test Case'!$C$2:$C$300,$A16,'Test Case'!$M$2:$M$300,"Chưa thực thi") -> 0 | F16: =C16+D16 -> 79 | G16: =IF(F16=0,0,C16/F16) -> 0.96202532
A17: Tổng | B17: =SUM(B11:B16) -> 299 | C17: =SUM(C11:C16) -> 289 | D17: =SUM(D11:D16) -> 8 | E17: =SUM(E11:E16) -> 2 | F17: =SUM(F11:F16) -> 297 | G17: =IF(F17=0,0,C17/F17) -> 0.97306397
A19: GHI CHÚ
A20: 1. Mỗi dòng trong sheet “Test Case” là một test case; các bước được đánh số trong cùng một ô. Cột “Kết quả” có danh sách chọn (Pass / Fail / Blocked / Chưa thực thi) và có thể chỉnh sửa; bảng thống kê trên tự cập nhật.
A21: 2. “Dữ liệu kiểm thử” được trích từ nội dung bước thực hiện (giá trị trong dấu ngoặc kép hoặc “vd …”) và cột dữ liệu của hệ thống quản lý test. Dấu “—” nghĩa là test case không nêu dữ liệu cụ thể.
A22: 3. “Kết quả thực tế”: với test case Pass ghi nhận đúng như kết quả mong đợi; với test case Fail lấy từ mô tả lỗi trên Jira (cột “Mã lỗi”). Báo cáo thực thi gốc không lưu văn bản kết quả thực tế riêng cho từng test case Pass.
A23: 4. BMH-T76 (Đăng nhập khi định dạng email không hợp lệ) và BMH-T381 (Xóa thông tin bệnh nhân) có trong bộ test case nhưng chưa có bản ghi thực thi. Ngược lại báo cáo thực thi có BMH-T2 và BMH-T14 (đã Pass) không còn trong tệp test case; hai test case này không được đưa vào file.

Sheet Test Case
A1: STT | B1: Mã TC | C1: Chức năng | D1: Chức năng con | E1: Tên test case | F1: Loại | G1: Ưu tiên | H1: Điều kiện tiên quyết | I1: Bước thực hiện | J1: Dữ liệu kiểm thử | K1: Kết quả mong đợi | L1: Kết quả thực tế | M1: Kết quả | N1: Ngày thực hiện | O1: Mã lỗi | P1: Ghi chú
A2: 1 | B2: BMH-T1 | C2: 01 - Đăng nhập | D2: Đăng nhập thành công với thông tin hợp lệ | E2: Đăng nhập bằng tài khoản hợp lệ | F2: Hợp lệ | G2: High | H2: Tài khoản đang hoạt động và có thông tin đăng nhập hợp lệ | I2: 1. Mở trang đăng nhập. 2. Nhập email hợp lệ. 3. Nhập password hợp lệ. 4. Nhấn Đăng nhập. | J2: email: admin@gmail.com password: 12345678 | K2: Đăng nhập thành công và chuyển tới giao diện | L2: Đúng như kết quả mong đợi. | M2: Pass | N2: 46314
A3: 2 | B3: BMH-T3 | C3: 01 - Đăng nhập | D3: Đăng nhập thất bại | E3: Đăng nhập khi mật khẩu không hợp lệ | F3: Không hợp lệ | G3: High | H3: Đang ở trang đăng nhập | I3: 1. Nhập email đúng địa chỉ và đúng định dạng 2. Nhập password không hợp lệ 3. Nhấn Đăng nhập. | J3: email: admin@gmail.com password: 12345 | K3: Không đăng nhập; hiển thị thông báo lỗi phù hợp. | L3: Đúng như kết quả mong đợi. | M3: Pass | N3: 46314
A4: 3 | B4: BMH-T76 | C4: 01 - Đăng nhập | D4: Đăng nhập thất bại | E4: Đăng nhập khi định dạng email không hợp lệ | F4: Không hợp lệ | G4: High | H4: Đang ở trang đăng nhập | I4: 1. Nhập email bị sai định dạng 2. Nhập password hợp lệ 3. Nhấn Đăng nhập. | J4: email: admin@gmail. password: 12345678 | K4: Không đăng nhập; hiển thị thông báo lỗi phù hợp. | M4: Chưa thực thi | P4: Chưa có bản ghi thực thi cho test case này trong báo cáo kết quả.
A5: 4 | B5: BMH-T77 | C5: 01 - Đăng nhập | D5: Đăng nhập thất bại | E5: Đăng nhập khi địa chỉ email không hợp lệ | F5: Không hợp lệ | G5: High | H5: Đang ở trang đăng nhập | I5: 1. Nhập email bị sai địa chỉ 2. Nhập password hợp lệ 3. Nhấn Đăng nhập. | J5: email: admin1@gmail.com password: 12345678 | K5: Không đăng nhập; hiển thị thông báo lỗi phù hợp. | L5: Đúng như kết quả mong đợi. | M5: Pass | N5: 46314
A6: 5 | B6: BMH-T78 | C6: 01 - Đăng nhập | D6: Đăng nhập thất bại | E6: Đăng nhập khi bỏ trống trường email | F6: Không hợp lệ | G6: High | H6: Đang ở trang đăng nhập | I6: 1. Bỏ trống trường email 2. Nhập password hợp lệ 3. Nhấn Đăng nhập. | J6: password: 1234578 | K6: Không đăng nhập; hiển thị thông báo lỗi phù hợp. | L6: Đúng như kết quả mong đợi. | M6: Pass | N6: 46314
A7: 6 | B7: BMH-T79 | C7: 01 - Đăng nhập | D7: Đăng nhập thất bại | E7: Đăng nhập khi bỏ trống trường password | F7: Không hợp lệ | G7: High | H7: Đang ở trang đăng nhập | I7: 1. Nhập email hợp lệ 2. Bỏ trống trường password 3. Nhấn Đăng nhập. | J7: email: admin@gmail.com | K7: Không đăng nhập; hiển thị thông báo lỗi phù hợp. | L7: Đúng như kết quả mong đợi. | M7: Pass | N7: 46314
A8: 7 | B8: BMH-T80 | C8: 01 - Đăng nhập | D8: Đăng nhập thất bại | E8: Đăng nhập khi bỏ trống trường email và password | F8: Không hợp lệ | G8: High | H8: Đang ở trang đăng nhập | I8: 1. Bỏ trống trường email 2. Bỏ trống trường password 3. Nhấn Đăng nhập. | J8: — | K8: Không đăng nhập; hiển thị thông báo lỗi phù hợp. | L8: Đúng như kết quả mong đợi. | M8: Pass | N8: 46314
A9: 8 | B9: BMH-T82 | C9: 01 - Đăng nhập | D9: Đăng nhập thất bại | E9: Đăng nhập khi địa chỉ email và password không hợp lệ | F9: Không hợp lệ | G9: High | H9: Đang ở trang đăng nhập | I9: 1. Nhập email bị sai địa chỉ 2. Nhập password không hợp lệ 3. Nhấn Đăng nhập. | J9: email: admin1@gmail. password: 1234567 | K9: Không đăng nhập; hiển thị thông báo lỗi phù hợp. | L9: Đúng như kết quả mong đợi. | M9: Pass | N9: 46314
A10: 9 | B10: BMH-T83 | C10: 01 - Đăng nhập | D10: Đăng nhập thất bại | E10: Đăng nhập khi email chưa được đăng kí | F10: Không hợp lệ | G10: High | H10: Đang ở trang đăng nhập | I10: 1. Nhập email chưa được đăng kí 2. Nhập password hợp lệ 3. Nhấn Đăng nhập. | J10: email: admin1234@gmail.com password: 12345678 | K10: Không đăng nhập; hiển thị thông báo lỗi phù hợp. | L10: Đúng như kết quả mong đợi. | M10: Pass | N10: 46314
A11: 10 | B11: BMH-T10 | C11: 02 - Quản lý bệnh nhân | D11: Thêm mới bệnh nhân | E11: Tạo hồ sơ bệnh nhân với dữ liệu hợp lệ | F11: Hợp lệ | G11: High | H11: Đăng nhập Admin; có quyền quản lý bệnh nhân | I11: 1. Mở Quản lý bệnh nhân. 2. Chọn Thêm mới. 3. Nhập các trường hợp lệ. 4. Lưu hồ sơ. | J11: — | K11: Hồ sơ được lưu; mã bệnh nhân duy nhất; dữ liệu hiển thị chính xác. | L11: Đúng như kết quả mong đợi. | M11: Pass | N11: 46314
A12: 11 | B12: BMH-T12 | C12: 02 - Quản lý bệnh nhân | D12: Quản lý danh sách bệnh nhân | E12: Cập nhật thông tin bệnh nhân | F12: Hợp lệ | G12: High | H12: Có hồ sơ bệnh nhân đang hoạt động | I12: 1. Tìm hồ sơ. 2. Chọn Sửa. 3. Thay đổi một hoặc nhiều trường được phép. 4. Lưu và mở lại hồ sơ. | J12: — | K12: Thông tin mới được lưu và hiển thị nhất quán. | L12: Đúng như kết quả mong đợi. | M12: Pass | N12: 46314
A13: 12 | B13: BMH-T15 | C13: 02 - Quản lý bệnh nhân | D13: Quản lý danh sách bệnh nhân | E13: Kiểm tra phân trang danh sách bệnh nhân | F13: Hợp lệ | G13: Normal | H13: Có ít nhất 11 hồ sơ phù hợp bộ lọc | I13: 1. Mở danh sách bệnh nhân. 2. Đếm số bản ghi trang đầu. 3. Chuyển trang tiếp theo. | J13: — | K13: Trang hiển thị tối đa 10 bệnh nhân theo SRS; phân trang điều hướng đúng. | L13: Đúng như kết quả mong đợi. | M13: Pass | N13: 46314
A14: 13 | B14: BMH-T16 | C14: 02 - Quản lý bệnh nhân | D14: Quản lý danh sách bệnh nhân | E14: Tìm kiếm bệnh nhân theo mã | F14: Hợp lệ | G14: Normal | H14: Có bệnh nhân với mã đã biết | I14: 1. Nhập mã bệnh nhân vào ô tìm kiếm. 2. Thực hiện tìm kiếm. | J14: — | K14: Hiển thị đúng hồ sơ tương ứng hoặc thông báo không có kết quả. | L14: Đúng như kết quả mong đợi. | M14: Pass | N14: 46314
A15: 14 | B15: BMH-T17 | C15: 02 - Quản lý bệnh nhân | D15: Quản lý danh sách bệnh nhân | E15: Tìm bệnh nhân bằng tên không dấu | F15: Hợp lệ | G15: Normal | H15: Có hồ sơ tên tiếng Việt có dấu | I15: 1. Nhập tên không dấu hoặc một phần tên. 2. Thực hiện tìm kiếm. | J15: — | K15: Trả về kết quả thông tin bệnh nhân | L15: Đúng như kết quả mong đợi. | M15: Pass | N15: 46314
A16: 15 | B16: BMH-T84 | C16: 02 - Quản lý bệnh nhân | D16: Quản lý danh sách bệnh nhân | E16: Tìm kiếm bệnh nhân theo họ và tên | F16: Hợp lệ | G16: Normal | H16: Có bệnh nhân với mã đã biết | I16: 1. Nhập họ và tên bệnh nhân vào ô tìm kiếm. 2. Thực hiện tìm kiếm. | J16: — | K16: Hiển thị đúng hồ sơ tương ứng hoặc thông báo không có kết quả. | L16: Đúng như kết quả mong đợi. | M16: Pass | N16: 46314
... A81: 80 | B81: BMH-T380 | C81: 02 - Quản lý bệnh nhân | D81: Thêm mới bệnh nhân | E81: Thêm bệnh nhân khi bỏ trống tất cả các trường | F81: Không hợp lệ | G81: High | H81: Đang ở giao diện điền thông tin bệnh nhân | I81: 1. Mở form thêm bệnh nhân. 2. Để trống tất cả các trường 3. Lưu. | J81: — | K81: Hệ thống báo lỗi và từ chối thêm bệnh nhân | L81: Đúng như kết quả mong đợi. | M81: Pass | N81: 46314
A82: 81 | B82: BMH-T381 | C82: 02 - Quản lý bệnh nhân | D82: Quản lý danh sách bệnh nhân | E82: Xóa thông tin bệnh nhân | F82: Hợp lệ | G82: High | H82: Có hồ sơ bệnh nhân đang hoạt động | I82: 1. Tìm hồ sơ. 2. Chọn Xóa | J82: — | K82: Hiển thị thông báo xóa bệnh nhân thành công | M82: Chưa thực thi | P82: Chưa có bản ghi thực thi cho test case này trong báo cáo kết quả.
A83: 82 | B83: BMH-T382 | C83: 04 - Quản lý thuốc | D83: Quản lý danh sách thuốc | E83: TC-THUOC-QL-POS-001 - Hiển thị danh sách thuốc | F83: Hợp lệ | G83: High | H83: Đăng nhập Admin; có dữ liệu thuốc | I83: 1. Vào Quản lý > Danh sách thuốc | J83: — | K83: Hiển thị các cột STT, Mã, Tên thuốc, Loại thuốc, Giá (VND), Đơn vị tính, Mô tả, Hành động; có ô tìm kiếm, nút Tìm kiếm và Thêm thuốc | L83: Đúng như kết quả mong đợi. | M83: Pass | N83: 46315
A84: 83 | B84: BMH-T383 | C84: 04 - Quản lý thuốc | D84: Quản lý danh sách thuốc | E84: TC-THUOC-QL-POS-002 - Kiểm tra dữ liệu hiển thị của một thuốc | F84: Hợp lệ | G84: Normal | H84: Đăng nhập Admin; Có ít nhất 1 thuốc | I84: 1. Mở danh sách 2. Đối chiếu một dòng với dữ liệu gốc | J84: — | K84: Mã, tên, loại, giá, đơn vị tính khớp dữ liệu thực tế | L84: Đúng như kết quả mong đợi. | M84: Pass | N84: 46315
A85: 84 | B85: BMH-T384 | C85: 04 - Quản lý thuốc | D85: Quản lý danh sách thuốc | E85: TC-THUOC-QL-POS-003 - Kiểm tra thứ tự sắp xếp danh sách | F85: Hợp lệ | G85: Low | H85: Đăng nhập Admin; Có nhiều thuốc | I85: 1. Mở danh sách 2. Quan sát thứ tự các dòng | J85: — | K85: Danh sách sắp xếp thống nhất (hiện thấy mã giảm dần, T000045 ở đầu) | L85: Đúng như kết quả mong đợi. | M85: Pass | N85: 46315
A86: 85 | B86: BMH-T385 | C86: 04 - Quản lý thuốc | D86: Quản lý danh sách thuốc | E86: TC-THUOC-QL-POS-004 - Tìm kiếm theo tên thuốc đầy đủ | F86: Hợp lệ | G86: High | H86: Đăng nhập Admin; Có thuốc tên xác định (vd Cetirizine 10mg) | I86: 1. Nhập tên đầy đủ vào ô tìm kiếm 2. Nhấn Tìm kiếm | J86: — | K86: Chỉ hiển thị thuốc có tên phù hợp | L86: Đúng như kết quả mong đợi. | M86: Pass | N86: 46315
A87: 86 | B87: BMH-T386 | C87: 04 - Quản lý thuốc | D87: Quản lý danh sách thuốc | E87: TC-THUOC-QL-POS-005 - Tìm kiếm theo một phần tên thuốc | F87: Hợp lệ | G87: High | H87: Đăng nhập Admin; Có nhiều thuốc cùng gốc tên (vd Vitamin) | I87: 1. Nhập "Vitamin" 2. Nhấn Tìm kiếm | J87: Bước 1: Vitamin | K87: Hiển thị tất cả thuốc có tên chứa từ khóa | L87: Đúng như kết quả mong đợi. | M87: Pass | N87: 46315
A88: 87 | B88: BMH-T387 | C88: 04 - Quản lý thuốc | D88: Quản lý danh sách thuốc | E88: TC-THUOC-QL-POS-006 - Tìm kiếm không phân biệt hoa thường | F88: Hợp lệ | G88: Normal | H88: Đăng nhập Admin; Có thuốc tên xác định | I88: 1. Nhập tên viết thường hoặc viết hoa toàn bộ 2. Nhấn Tìm kiếm | J88: — | K88: Kết quả giống nhau dù viết hoa hay thường | L88: Đúng như kết quả mong đợi. | M88: Pass | N88: 46315
A89: 88 | B89: BMH-T388 | C89: 04 - Quản lý thuốc | D89: Quản lý danh sách thuốc | E89: TC-THUOC-QL-POS-007 - Tìm kiếm bằng phím Enter | F89: Hợp lệ | G89: Low | H89: Đăng nhập Admin; Có thuốc tên xác định | I89: 1. Nhập tên thuốc 2. Nhấn Enter | J89: — | K89: Hệ thống tìm kiếm giống khi nhấn nút Tìm kiếm | L89: Đúng như kết quả mong đợi. | M89: Pass | N89: 46315
A90: 89 | B90: BMH-T389 | C90: 04 - Quản lý thuốc | D90: Quản lý danh sách thuốc | E90: TC-THUOC-QL-POS-008 - Xóa từ khóa để hiển thị lại toàn bộ danh sách | F90: Hợp lệ | G90: Normal | H90: Đăng nhập Admin; Đã tìm kiếm một từ khóa | I90: 1. Xóa nội dung ô tìm kiếm 2. Nhấn Tìm kiếm | J90: — | K90: Danh sách hiển thị lại đầy đủ các thuốc | L90: Đúng như kết quả mong đợi. | M90: Pass | N90: 46315
A91: 90 | B91: BMH-T390 | C91: 04 - Quản lý thuốc | D91: Quản lý danh sách thuốc | E91: TC-THUOC-QL-POS-009 - Kiểm tra định dạng cột Giá (VND) | F91: Hợp lệ | G91: Normal | H91: Đăng nhập Admin; Có thuốc giá từ 1.000 trở lên | I91: 1. Quan sát cột Giá (VND) | J91: — | K91: Giá có dấu phân cách hàng nghìn (vd 1.200, 6.000) và khớp giá đã lưu | L91: Đúng như kết quả mong đợi. | M91: Pass | N91: 46315
A92: 91 | B92: BMH-T391 | C92: 04 - Quản lý thuốc | D92: Quản lý danh sách thuốc | E92: TC-THUOC-QL-POS-010 - Mở mô tả thuốc bằng nút Xem | F92: Hợp lệ | G92: High | H92: Đăng nhập Admin; Có thuốc có mô tả | I92: 1. Nhấn nút Xem ở một dòng | J92: — | K92: Hộp thoại "Mô tả" hiển thị với nội dung mô tả của thuốc | L92: Đúng như kết quả mong đợi. | M92: Pass | N92: 46315
A93: 92 | B93: BMH-T392 | C93: 04 - Quản lý thuốc | D93: Quản lý danh sách thuốc | E93: TC-THUOC-QL-POS-011 - Nội dung mô tả khớp với thuốc đã chọn | F93: Hợp lệ | G93: Normal | H93: Đăng nhập Admin; Có ít nhất 2 thuốc mô tả khác nhau | I93: 1. Nhấn Xem ở thuốc A 2. Đóng hộp thoại 3. Nhấn Xem ở thuốc B | J93: — | K93: Mỗi lần hiển thị đúng mô tả của thuốc tương ứng | L93: Đúng như kết quả mong đợi. | M93: Pass | N93: 46315
A94: 93 | B94: BMH-T393 | C94: 04 - Quản lý thuốc | D94: Quản lý danh sách thuốc | E94: TC-THUOC-QL-POS-012 - Đóng hộp thoại mô tả | F94: Hợp lệ | G94: Normal | H94: Đăng nhập Admin; Đang mở hộp thoại mô tả | I94: 1. Nhấn nút Close 2. Mở lại hộp thoại 3. Nhấn biểu tượng X ở góc | J94: — | K94: Cả hai cách đều đóng hộp thoại và quay lại danh sách | L94: Đúng như kết quả mong đợi. | M94: Pass | N94: 46315
... A207: 206 | B207: BMH-T521 | C207: 05 - Quản lý thẻ BHYT | D207: Thêm thẻ BHYT | E207: TC-BHYT-ADD-NEG-007 - Bỏ trống toàn bộ trường bắt buộc | F207: Không hợp lệ | G207: High | H207: Đăng nhập Admin; Đang ở màn hình Thêm | I207: 1. Không nhập gì 2. Nhấn Lưu lại | J207: — | K207: Không tạo thẻ; cảnh báo ở tất cả trường bắt buộc; không lỗi hệ thống | L207: Đúng như kết quả mong đợi. | M207: Pass | N207: 46316
A208: 207 | B208: BMH-T522 | C208: 05 - Quản lý thẻ BHYT | D208: Thêm thẻ BHYT | E208: TC-BHYT-ADD-NEG-008 - Mã số chứa chữ cái | F208: Không hợp lệ | G208: Normal | H208: Đăng nhập Admin; Đang ở màn hình Thêm | I208: 1. Nhập "abc12" vào Mã số 2. Điền các trường còn lại 3. Nhấn Lưu lại | J208: Bước 1: abc12 | K208: Hệ thống từ chối hoặc chặn nhập, hiển thị cảnh báo | L208: Hệ thống cho phép nhập và lưu dữ liệu thành công. | M208: Fail | N208: 46316 | O208: BMH-1
A209: 208 | B209: BMH-T523 | C209: 05 - Quản lý thẻ BHYT | D209: Thêm thẻ BHYT | E209: TC-BHYT-ADD-NEG-009 - Mã số chứa ký tự đặc biệt hoặc khoảng trắng | F209: Không hợp lệ | G209: Normal | H209: Đăng nhập Admin; Đang ở màn hình Thêm | I209: 1. Nhập "12 34" hoặc "@#$%" vào Mã số 2. Điền các trường còn lại 3. Nhấn Lưu lại | J209: Bước 1: 12 34 Bước 1: @#$% | K209: Hệ thống từ chối hoặc chặn nhập, hiển thị cảnh báo; không lưu mã số sai định dạng | L209: Hệ thống cho phép nhập và lưu dữ liệu thành công. | M209: Fail | N209: 46316 | O209: BMH-2
A210: 209 | B210: BMH-T524 | C210: 05 - Quản lý thẻ BHYT | D210: Thêm thẻ BHYT | E210: TC-BHYT-ADD-NEG-010 - Mã số quá ngắn | F210: Không hợp lệ | G210: Normal | H210: Đăng nhập Admin; Đang ở màn hình Thêm | I210: 1. Nhập Mã số 1 chữ số (vd 1) 2. Điền các trường còn lại 3. Nhấn Lưu lại | J210: Bước 1: 1 | K210: Nếu có quy tắc độ dài tối thiểu, hệ thống từ chối và thông báo; nếu không, đánh giá theo yêu cầu thực tế | L210: Hệ thống cho phép nhập và lưu dữ liệu thành công. | M210: Fail | N210: 46316 | O210: BMH-3
A211: 210 | B211: BMH-T525 | C211: 05 - Quản lý thẻ BHYT | D211: Thêm thẻ BHYT | E211: TC-BHYT-ADD-NEG-011 - Mã số quá dài | F211: Không hợp lệ | G211: Normal | H211: Đăng nhập Admin; Đang ở màn hình Thêm | I211: 1. Nhập Mã số trên 20 chữ số 2. Điền các trường còn lại 3. Nhấn Lưu lại | J211: — | K211: Hệ thống từ chối hoặc cắt theo giới hạn; không lỗi, giao diện danh sách không vỡ | L211: Hệ thống lưu dữ liệu thẻ BHYT thành công. | M211: Fail | N211: 46316 | O211: BMH-7
A212: 211 | B212: BMH-T526 | C212: 05 - Quản lý thẻ BHYT | D212: Thêm thẻ BHYT | E212: TC-BHYT-ADD-NEG-012 - Mã số trùng với thẻ đã có | F212: Không hợp lệ | G212: High | H212: Đăng nhập Admin; Đã có thẻ mã số xác định | I212: 1. Nhập Mã số trùng thẻ đã có 2. Điền các trường còn lại 3. Nhấn Lưu lại | J212: — | K212: Nếu cấm trùng mã số, hệ thống từ chối và thông báo; nếu cho phép, đánh giá theo quy tắc thực tế | L212: Hệ thống cho phép nhập và lưu dữ liệu thành công. | M212: Fail | N212: 46316 | O212: BMH-4
A213: 212 | B213: BMH-T527 | C213: 05 - Quản lý thẻ BHYT | D213: Thêm thẻ BHYT | E213: TC-BHYT-ADD-NEG-013 - Nơi đăng ký khám chỉ chứa khoảng trắng | F213: Không hợp lệ | G213: Normal | H213: Đăng nhập Admin; Đang ở màn hình Thêm | I213: 1. Nhập toàn khoảng trắng vào Nơi đăng ký khám 2. Điền các trường còn lại 3. Nhấn Lưu lại | J213: — | K213: Hệ thống coi như trống, không lưu và cảnh báo | L213: Đúng như kết quả mong đợi. | M213: Pass | N213: 46316
A214: 213 | B214: BMH-T528 | C214: 05 - Quản lý thẻ BHYT | D214: Thêm thẻ BHYT | E214: TC-BHYT-ADD-NEG-014 - Nơi cấp chỉ chứa khoảng trắng | F214: Không hợp lệ | G214: Normal | H214: Đăng nhập Admin; Đang ở màn hình Thêm | I214: 1. Nhập toàn khoảng trắng vào Nơi cấp 2. Điền các trường còn lại 3. Nhấn Lưu lại | J214: — | K214: Hệ thống coi như trống, không lưu và cảnh báo | L214: Đúng như kết quả mong đợi. | M214: Pass | N214: 46316
A215: 214 | B215: BMH-T529 | C215: 05 - Quản lý thẻ BHYT | D215: Thêm thẻ BHYT | E215: TC-BHYT-ADD-NEG-015 - Nơi đăng ký khám và Nơi cấp quá dài | F215: Không hợp lệ | G215: Low | H215: Đăng nhập Admin; Đang ở màn hình Thêm | I215: 1. Nhập chuỗi trên 255 ký tự vào Nơi đăng ký khám và Nơi cấp 2. Điền các trường còn lại 3. Nhấn Lưu lại | J215: — | K215: Hệ thống từ chối hoặc cắt theo giới hạn; không lỗi, giao diện danh sách không vỡ | L215: Đúng như kết quả mong đợi. | M215: Pass | N215: 46316
A216: 215 | B216: BMH-T530 | C216: 05 - Quản lý thẻ BHYT | D216: Thêm thẻ BHYT | E216: TC-BHYT-ADD-NEG-016 - Nơi đăng ký khám chứa mã script | F216: Không hợp lệ | G216: Normal | H216: Đăng nhập Admin; Đang ở màn hình Thêm | I216: 1. Nhập vào Nơi đăng ký khám 2. Điền các trường còn lại 3. Nhấn Lưu lại 4. Mở danh sách | J216: — | K216: Hệ thống xử lý an toàn, không thực thi script khi hiển thị trong danh sách | L216: Đúng như kết quả mong đợi. | M216: Pass | N216: 46317
...
